Workbook

Sheet Read Me
A1: Vehicle Manager Bangladesh: economy model v0.1
A3: Purpose: check that the money and time numbers feel right before any code is written.
A4: How to use: change blue cells (yellow = main levers on the Settings sheet). Black cells are formulas, green cells link to another sheet.
A5: Sheets: Settings (levers), Vehicles (12 tiers), Operating Permits (one-time Taka purchases that unlock tiers), Routes, Cargo, Tolls, Trip Calculator (one row per scenario), First Hour (purchase simulation).
A6: All money is in Taka. Time: 'game hours' are in-world time, 'real minutes or hours' are what the player waits at 1x speed.
A8: Key results (live)
A9: Purchases in the first 60 minutes | B9: ='First Hour'!G4 -> 3
A10: Purchases in the first 4 hours | B10: ='First Hour'!G5 -> 4
A11: Fleet profit per real hour once Turbo Start ends (Tk) | B11: ='First Hour'!G6 -> 247606.66
A12: Tiers inside their payback target | B12: =COUNTIF('Trip Calculator'!AC5:AC16,"OK")&" of 12" -> 12 of 12
A14: Tier and typical route | B14: Payback (real h) | C14: Target (real h) | D14: Status | E14: Profit per trip (Tk)
A15: ='Trip Calculator'!F5&" on "&'Trip Calculator'!C5&" ("&'Trip Calculator'!D5&")" -> Sonar Van on M01 (Market goods) | B15: ='Trip Calculator'!AA5 -> 0.90794713 | C15: ='Trip Calculator'!AB5 -> 0.5 to 5 | D15: ='Trip Calculator'!AC5 -> OK | E15: ='Trip Calculator'!W5 -> 385.485
A16: ='Trip Calculator'!F6&" on "&'Trip Calculator'!C6&" ("&'Trip Calculator'!D6&")" -> Bijli Cargo on M02 (Parcels) | B16: ='Trip Calculator'!AA6 -> 3.2402792 | C16: ='Trip Calculator'!AB6 -> 1 to 10 | D16: ='Trip Calculator'!AC6 -> OK | E16: ='Trip Calculator'!W6 -> 1003
A17: ='Trip Calculator'!F7&" on "&'Trip Calculator'!C7&" ("&'Trip Calculator'!D7&")" -> Tuntuni Mini on R01 (Parcels) | B17: ='Trip Calculator'!AA7 -> 13.35154 | C17: ='Trip Calculator'!AB7 -> 5 to 30 | D17: ='Trip Calculator'!AC7 -> OK | E17: ='Trip Calculator'!W7 -> 1830.8333
A18: ='Trip Calculator'!F8&" on "&'Trip Calculator'!C8&" ("&'Trip Calculator'!D8&")" -> Sathi Plus on R01 (General dry) | B18: ='Trip Calculator'!AA8 -> 14.405002 | C18: ='Trip Calculator'!AB8 -> 5 to 30 | D18: ='Trip Calculator'!AC8 -> OK | E18: ='Trip Calculator'!W8 -> 2105.75
A19: ='Trip Calculator'!F9&" on "&'Trip Calculator'!C9&" ("&'Trip Calculator'!D9&")" -> Meghna 14 on R04 (Parcels) | B19: ='Trip Calculator'!AA9 -> 11.782416 | C19: ='Trip Calculator'!AB9 -> 10 to 40 | D19: ='Trip Calculator'!AC9 -> OK | E19: ='Trip Calculator'!W9 -> 13163.056
A20: ='Trip Calculator'!F10&" on "&'Trip Calculator'!C10&" ("&'Trip Calculator'!D10&")" -> Jamuna Open on R05 (General dry) | B20: ='Trip Calculator'!AA10 -> 20.559839 | C20: ='Trip Calculator'!AB10 -> 10 to 40 | D20: ='Trip Calculator'!AC10 -> OK | E20: ='Trip Calculator'!W10 -> 23995
A21: ='Trip Calculator'!F11&" on "&'Trip Calculator'!C11&" ("&'Trip Calculator'!D11&")" -> Karnaphuli 20 on R06 (Garments) | B21: ='Trip Calculator'!AA11 -> 13.612926 | C21: ='Trip Calculator'!AB11 -> 10 to 40 | D21: ='Trip Calculator'!AC11 -> OK | E21: ='Trip Calculator'!W11 -> 44994
A22: ='Trip Calculator'!F12&" on "&'Trip Calculator'!C12&" ("&'Trip Calculator'!D12&")" -> Himaloy Reefer on R10 (Fish) | B22: ='Trip Calculator'!AA12 -> 22.271479 | C22: ='Trip Calculator'!AB12 -> 10 to 40 | D22: ='Trip Calculator'!AC12 -> OK | E22: ='Trip Calculator'!W12 -> 26940.286
A23: ='Trip Calculator'!F13&" on "&'Trip Calculator'!C13&" ("&'Trip Calculator'!D13&")" -> Pahari Tipper on R14 (Sand and stone) | B23: ='Trip Calculator'!AA13 -> 32.970162 | C23: ='Trip Calculator'!AB13 -> 20 to 80 | D23: ='Trip Calculator'!AC13 -> OK | E23: ='Trip Calculator'!W13 -> 11121.167
A24: ='Trip Calculator'!F14&" on "&'Trip Calculator'!C14&" ("&'Trip Calculator'!D14&")" -> Telrani on R05 (Fuel) | B24: ='Trip Calculator'!AA14 -> 20.560995 | C24: ='Trip Calculator'!AB14 -> 20 to 80 | D24: ='Trip Calculator'!AC14 -> OK | E24: ='Trip Calculator'!W14 -> 39082.321
A25: ='Trip Calculator'!F15&" on "&'Trip Calculator'!C15&" ("&'Trip Calculator'!D15&")" -> Bongo Mover 40 on R05 (Containers) | B25: ='Trip Calculator'!AA15 -> 23.296886 | C25: ='Trip Calculator'!AB15 -> 20 to 80 | D25: ='Trip Calculator'!AC15 -> OK | E25: ='Trip Calculator'!W15 -> 49490.571
A26: ='Trip Calculator'!F16&" on "&'Trip Calculator'!C16&" ("&'Trip Calculator'!D16&")" -> Hati Lowbed on R05 (Heavy machinery) | B26: ='Trip Calculator'!AA16 -> 25.141985 | C26: ='Trip Calculator'!AB16 -> 20 to 80 | D26: ='Trip Calculator'!AC16 -> OK | E26: ='Trip Calculator'!W16 -> 74245

Sheet Settings
A1: Global settings and balancing levers
A2: Blue = input you can change. Yellow = key balancing lever. Every other sheet reads from here.
A4: Setting | B4: Value | C4: Unit | D4: Source or reasoning
A5: Diesel price | B5: 135 | C5: Tk per litre | D5: Real. EMRD order, effective 21 Sep 2026 (research doc). Move by +/- Tk 15-20 for fuel shock events.
A6: Base fare per ton (loading component) | B6: 300 | C6: Tk per ton | D6: Fitted to real fares: 6-wheel truck in Dhaka about Tk 4,700 for 20 km and Tk 24,000 Dhaka-Chattogram for 10 t (Jugantor, 9 Oct 2026).
A7: Freight rate per ton-km | B7: 8.5 | C7: Tk per ton-km | D7: Fitted together with the base fare above. Gives about Tk 42,000 for 10 t over 450 km, close to the Chattogram-North fare after the diesel hike.
A8: Freight multiplier | B8: 1.5 | C8: x | D8: 1.0 = real Bangladesh freight rates. At 1.0 a starter pickup needs about 30 real hours to pay for itself and the first hour has only 2 purchases, which is too slow. 1.5 is the chosen default: fares stay plausible while vehicle prices, diesel and tolls stay fully real.
A9: Game minutes per real minute | B9: 60 | C9: x | D9: 60 means 1 game hour passes in 1 real minute, so 1 game day = 24 real minutes. Dhaka-Chattogram takes about 9 real minutes.
A10: Turbo Start phase 1 ends at | B10: 20 | C10: real minutes | D10: Truck Manager uses a Turbo Start that makes dispatches up to 200x quicker at the beginning. Ours tapers to avoid a sudden income cliff.
A11: Turbo Start phase 1 speed | B11: 20 | C11: x | D11: Game design value.
A12: Turbo Start phase 2 ends at | B12: 40 | C12: real minutes | D12: Game design value.
A13: Turbo Start phase 2 speed | B13: 10 | C13: x | D13: Game design value.
A14: Turbo Start phase 3 ends at | B14: 60 | C14: real minutes | D14: After this the game runs at 1x.
A15: Turbo Start phase 3 speed | B15: 5 | C15: x | D15: Game design value.
A16: Starting cash | B16: 1500000 | C16: Tk | D16: Game design value. Player also gets one free Sathi Plus pickup (tier 4).
... A28: Resale share of price | B28: 0.6 | C28: fraction | D28: Game design value. A vehicle sells for this share of its price, so buying and selling straight away loses the rest. A vehicle on the road cannot be sold: unassign it, let the trip finish, then sell.

Sheet Tolls
A1: Toll per crossing (Tk, one way)
A2: Padma: gazette rates, May 2022. Jamuna: Bridge Authority notice, Nov 2021. Meghna+Gumti and Paturia ferry are partly approximate (see comments).
A4: Toll class | B4: None | C4: Padma Bridge | D4: Jamuna Bridge | E4: Meghna+Gumti | F4: Paturia Ferry
A5: Not on highway | B5: 0 | C5: 0 | D5: 0 | E5: 0 | F5: 0
A6: Light | B6: 0 | C6: 1200 | D6: 600 | E6: 180 | F6: 600
A7: Small truck | B7: 0 | C7: 1600 | D7: 1000 | E7: 500 | F7: 740
A8: Medium truck | B8: 0 | C8: 2800 | D8: 1600 | E8: 800 | F8: 1460
A9: Big truck | B9: 0 | C9: 5500 | D9: 2000 | E9: 1000 | F9: 2000
A10: Trailer | B10: 0 | C10: 6000 | D10: 3000 | E10: 2500 | F10: 2800
A11: Trailer+1 axle | B11: 0 | C11: 7500 | D11: 4000 | E11: 3000 | F11: 3500

Sheet Cargo
A1: Cargo types
A3: Cargo | B3: Rate factor | C3: Allowed tiers (comma separated, no spaces) | D3: Reasoning
A4: Market goods | B4: 1.2 | C4: 1,2 | D4: Short bazaar runs.
A5: Parcels | B5: 1.5 | C5: 2,3,4,5 | D5: E-commerce pays a premium for speed and small lots.
A6: General dry | B6: 1 | C6: 3,4,5,6,7,11 | D6: Baseline. Tier 11 included so prime movers can haul general freight in the MVP. All fares are fitted to this.
A7: Vegetables | B7: 1.2 | C7: 3,4,5,6 | D7: Perishable, from northern districts to Dhaka.
A8: Garments | B8: 1.4 | C8: 5,6,7 | D8: Export deadline at the port. Missing it costs a penalty (later feature).
A9: Rice | B9: 1 | C9: 4,5,6,7 | D9: Bulk, steady demand.
A10: Cement and rod | B10: 0.9 | C10: 6,9 | D10: Heavy, low value per ton.
A11: Sand and stone | B11: 0.9 | C11: 9 | D11: Heavy, low value per ton.
A12: Fish | B12: 2.2 | C12: 8 | D12: Reefer only. Needs the cold chain license.
A13: Fuel | B13: 1.2 | C13: 10 | D13: Hazardous. Needs a special license.
A14: Containers | B14: 1.2 | C14: 11 | D14: Port to ICD and Dhaka.
A15: Heavy machinery | B15: 1.2 | C15: 12 | D15: Low-bed only. Special permit.

Sheet Vehicles
A1: Vehicle tiers
A2: Prices from dealer listings (research doc, indicative). Speed, mileage, maintenance, wages and premiums are game values based on that research.
A4: Tier | B4: Name (fictional) | C4: Real-world equivalent | D4: Price (lakh Tk) | E4: Price (Tk) | F4: Legal payload (t) | G4: Max load with overload (t) | H4: Highway speed (km/h) | I4: Mileage (km/L, 0 = not diesel) | J4: Other energy (Tk/km) | K4: Energy cost (Tk/km) | L4: Maintenance (Tk/km) | M4: Crew wage (Tk per game hour) | N4: Load + unload time (game h) | O4: Small-load premium | P4: Toll class | Q4: Allowed on highway? | R4: Unlock: operating permit id (blank = none, see Operating Permits sheet) | S4: Target payback min (real h) | T4: Target payback max (real h) | U4: Allowed routes (comma separated, no spaces, blank = any route) | V4: Unlock: deliveries needed (0 = none)
A5: 1 | B5: Sonar Van | C5: Pedal van | D5: 0.2 | E5: =D5*100000 -> 20000 | F5: 0.3 | G5: 0.5 | H5: 8 | I5: 0 | J5: 0 | K5: =IF(I5>0,Settings!$B$5/I5,J5) -> 0 | L5: 0.2 | M5: 50 | N5: 0.3 | O5: 2.5 | P5: Not on highway | Q5: No | S5: 0.5 | T5: 5 | U5: M01,M02 | V5: 0
A6: 2 | B6: Bijli Cargo | C6: Battery cargo 3-wheeler | D6: 1.5 | E6: =D6*100000 -> 150000 | F6: 0.5 | G6: 0.8 | H6: 20 | I6: 0 | J6: 1.5 | K6: =IF(I6>0,Settings!$B$5/I6,J6) -> 1.5 | L6: 0.5 | M6: 60 | N6: 0.3 | O6: 2.7 | P6: Not on highway | Q6: No | S6: 1 | T6: 10 | V6: 0
A7: 3 | B7: Tuntuni Mini | C7: Tata Ace class | D7: 10 | E7: =D7*100000 -> 1000000 | F7: 0.8 | G7: 1.5 | H7: 45 | I7: 15 | J7: 0 | K7: =IF(I7>0,Settings!$B$5/I7,J7) -> 9 | L7: 1.5 | M7: 70 | N7: 0.5 | O7: 3 | P7: Light | Q7: Yes | S7: 5 | T7: 30 | V7: 5
A8: 4 | B8: Sathi Plus | C8: 1.5 t pickup (Dost class) | D8: 13 | E8: =D8*100000 -> 1300000 | F8: 1.5 | G8: 3 | H8: 50 | I8: 12 | J8: 0 | K8: =IF(I8>0,Settings!$B$5/I8,J8) -> 11.25 | L8: 2 | M8: 80 | N8: 0.5 | O8: 2.8 | P8: Light | Q8: Yes | S8: 5 | T8: 30 | V8: 0
A9: 5 | B9: Meghna 14 | C9: 14 ft covered van | D9: 25 | E9: =D9*100000 -> 2500000 | F9: 4 | G9: 7 | H9: 45 | I9: 8 | J9: 0 | K9: =IF(I9>0,Settings!$B$5/I9,J9) -> 16.875 | L9: 3 | M9: 110 | N9: 1 | O9: 1.6 | P9: Small truck | Q9: Yes | R9: light | S9: 10 | T9: 40 | V9: 0
A10: 6 | B10: Jamuna Open | C10: 6-wheel truck (LPT 1615 class) | D10: 32 | E10: =D10*100000 -> 3200000 | F10: 10 | G10: 22 | H10: 40 | I10: 4.5 | J10: 0 | K10: =IF(I10>0,Settings!$B$5/I10,J10) -> 30 | L10: 4 | M10: 160 | N10: 2 | O10: 1 | P10: Medium truck | Q10: Yes | R10: medium | S10: 10 | T10: 40 | V10: 0
A11: 7 | B11: Karnaphuli 20 | C11: 20-23 ft covered van | D11: 35 | E11: =D11*100000 -> 3500000 | F11: 10 | G11: 18 | H11: 40 | I11: 4.5 | J11: 0 | K11: =IF(I11>0,Settings!$B$5/I11,J11) -> 30 | L11: 4.5 | M11: 160 | N11: 2 | O11: 1.05 | P11: Medium truck | Q11: Yes | R11: medium | S11: 10 | T11: 40 | V11: 0
A12: 8 | B12: Himaloy Reefer | C12: Freezer van | D12: 45 | E12: =D12*100000 -> 4500000 | F12: 6 | G12: 7 | H12: 40 | I12: 3.5 | J12: 0 | K12: =IF(I12>0,Settings!$B$5/I12,J12) -> 38.571429 | L12: 6 | M12: 180 | N12: 2 | O12: 1 | P12: Medium truck | Q12: Yes | R12: coldchain | S12: 10 | T12: 40 | V12: 0
A13: 9 | B13: Pahari Tipper | C13: 10-wheel tipper | D13: 60 | E13: =D13*100000 -> 6000000 | F13: 18 | G13: 30 | H13: 30 | I13: 3 | J13: 0 | K13: =IF(I13>0,Settings!$B$5/I13,J13) -> 45 | L13: 7 | M13: 170 | N13: 1.5 | O13: 1.2 | P13: Big truck | Q13: Yes | R13: heavy | S13: 20 | T13: 80 | V13: 0
A14: 10 | B14: Telrani | C14: Fuel tanker | D14: 50 | E14: =D14*100000 -> 5000000 | F14: 12.75 | G14: 12.75 | H14: 35 | I14: 3.5 | J14: 0 | K14: =IF(I14>0,Settings!$B$5/I14,J14) -> 38.571429 | L14: 6 | M14: 200 | N14: 1.5 | O14: 1 | P14: Big truck | Q14: Yes | R14: hazmat | S14: 20 | T14: 80 | V14: 0
A15: 11 | B15: Bongo Mover 40 | C15: Prime mover + 40 ft trailer | D15: 65 | E15: =D15*100000 -> 6500000 | F15: 28 | G15: 35 | H15: 35 | I15: 2.5 | J15: 0 | K15: =IF(I15>0,Settings!$B$5/I15,J15) -> 54 | L15: 9 | M15: 220 | N15: 2.5 | O15: 0.6 | P15: Trailer | Q15: Yes | R15: heavy | S15: 20 | T15: 80 | V15: 0
A16: 12 | B16: Hati Lowbed | C16: Low-bed trailer | D16: 80 | E16: =D16*100000 -> 8000000 | F16: 40 | G16: 40 | H16: 25 | I16: 2 | J16: 0 | K16: =IF(I16>0,Settings!$B$5/I16,J16) -> 67.5 | L16: 12 | M16: 260 | N16: 3 | O16: 0.6 | P16: Trailer+1 axle | Q16: Yes | R16: heavy | S16: 20 | T16: 80 | V16: 0

Sheet Operating Permits
A1: Operating permits
A2: One-time Taka purchases. A vehicle with an unlock permit id in the Vehicles sheet (column R) needs that permit; tier 3 needs deliveries instead (column V).
A3: Permit id | B3: Name | C3: Price (Tk) | D3: Unlocks tiers (comma separated, no spaces) | E3: Cheapest unlocked tier | F3: Permit price as share of that vehicle's price | G3: Payback of that vehicle without the permit (real h, typical route) | H3: Payback with the permit (real h) | I3: Target payback max (real h) | J3: Reasoning
A4: light | B4: Light operating permit | C4: 400000 | D4: 5 | E4: 5 | F4: =ROUND(C4/INDEX(Vehicles!$E$5:$E$16,MATCH(E4,Vehicles!$A$5:$A$16,0)),3) -> 0.16 | G4: =ROUND(INDEX(Vehicles!$E$5:$E$16,MATCH(E4,Vehicles!$A$5:$A$16,0))/INDEX('Trip Calculator'!$Z$5:$Z$16,MATCH(E4,'Trip Calculator'!$B$5:$B$16,0)),1) -> 11.8 | H4: =ROUND((INDEX(Vehicles!$E$5:$E$16,MATCH(E4,Vehicles!$A$5:$A$16,0))+C4)/INDEX('Trip Calculator'!$Z$5:$Z$16,MATCH(E4,'Trip Calculator'!$B$5:$B$16,0)),1) -> 13.7 | I4: =INDEX(Vehicles!$T$5:$T$16,MATCH(E4,Vehicles!$A$5:$A$16,0)) -> 40 | J4: Confirmed price: about 15 to 17 percent of the cheapest vehicle it unlocks. It adds about 2 to 5.5 real hours to that vehicle's payback at 1x (columns G and H, typical route) and keeps it inside its target range. One-time purchase in Taka, never a premium currency.
A5: medium | B5: Medium operating permit | C5: 500000 | D5: 6,7 | E5: 6 | F5: =ROUND(C5/INDEX(Vehicles!$E$5:$E$16,MATCH(E5,Vehicles!$A$5:$A$16,0)),3) -> 0.156 | G5: =ROUND(INDEX(Vehicles!$E$5:$E$16,MATCH(E5,Vehicles!$A$5:$A$16,0))/INDEX('Trip Calculator'!$Z$5:$Z$16,MATCH(E5,'Trip Calculator'!$B$5:$B$16,0)),1) -> 20.6 | H5: =ROUND((INDEX(Vehicles!$E$5:$E$16,MATCH(E5,Vehicles!$A$5:$A$16,0))+C5)/INDEX('Trip Calculator'!$Z$5:$Z$16,MATCH(E5,'Trip Calculator'!$B$5:$B$16,0)),1) -> 23.8 | I5: =INDEX(Vehicles!$T$5:$T$16,MATCH(E5,Vehicles!$A$5:$A$16,0)) -> 40 | J5: Same rule as above.
A6: coldchain | B6: Cold chain operating permit | C6: 700000 | D6: 8 | E6: 8 | F6: =ROUND(C6/INDEX(Vehicles!$E$5:$E$16,MATCH(E6,Vehicles!$A$5:$A$16,0)),3) -> 0.156 | G6: =ROUND(INDEX(Vehicles!$E$5:$E$16,MATCH(E6,Vehicles!$A$5:$A$16,0))/INDEX('Trip Calculator'!$Z$5:$Z$16,MATCH(E6,'Trip Calculator'!$B$5:$B$16,0)),1) -> 22.3 | H6: =ROUND((INDEX(Vehicles!$E$5:$E$16,MATCH(E6,Vehicles!$A$5:$A$16,0))+C6)/INDEX('Trip Calculator'!$Z$5:$Z$16,MATCH(E6,'Trip Calculator'!$B$5:$B$16,0)),1) -> 25.7 | I6: =INDEX(Vehicles!$T$5:$T$16,MATCH(E6,Vehicles!$A$5:$A$16,0)) -> 40 | J6: Same rule as above.
A7: hazmat | B7: Hazmat operating permit | C7: 800000 | D7: 10 | E7: 10 | F7: =ROUND(C7/INDEX(Vehicles!$E$5:$E$16,MATCH(E7,Vehicles!$A$5:$A$16,0)),3) -> 0.16 | G7: =ROUND(INDEX(Vehicles!$E$5:$E$16,MATCH(E7,Vehicles!$A$5:$A$16,0))/INDEX('Trip Calculator'!$Z$5:$Z$16,MATCH(E7,'Trip Calculator'!$B$5:$B$16,0)),1) -> 20.6 | H7: =ROUND((INDEX(Vehicles!$E$5:$E$16,MATCH(E7,Vehicles!$A$5:$A$16,0))+C7)/INDEX('Trip Calculator'!$Z$5:$Z$16,MATCH(E7,'Trip Calculator'!$B$5:$B$16,0)),1) -> 23.9 | I7: =INDEX(Vehicles!$T$5:$T$16,MATCH(E7,Vehicles!$A$5:$A$16,0)) -> 80 | J7: Same rule as above.
A8: heavy | B8: Heavy operating permit | C8: 1000000 | D8: 9,11,12 | E8: 9 | F8: =ROUND(C8/INDEX(Vehicles!$E$5:$E$16,MATCH(E8,Vehicles!$A$5:$A$16,0)),3) -> 0.167 | G8: =ROUND(INDEX(Vehicles!$E$5:$E$16,MATCH(E8,Vehicles!$A$5:$A$16,0))/INDEX('Trip Calculator'!$Z$5:$Z$16,MATCH(E8,'Trip Calculator'!$B$5:$B$16,0)),1) -> 33 | H8: =ROUND((INDEX(Vehicles!$E$5:$E$16,MATCH(E8,Vehicles!$A$5:$A$16,0))+C8)/INDEX('Trip Calculator'!$Z$5:$Z$16,MATCH(E8,'Trip Calculator'!$B$5:$B$16,0)),1) -> 38.5 | I8: =INDEX(Vehicles!$T$5:$T$16,MATCH(E8,Vehicles!$A$5:$A$16,0)) -> 80 | J8: Same rule as above.

Sheet Routes
A1: Routes
A2: Distances are approximate road km. Replace with OSRM output during data prep. Daily demand is a game value per route.
A4: Route ID | B4: From | C4: To | D4: Distance (km, one way) | E4: Haul type | F4: Crossing | G4: Weighbridges | H4: Extra delay (game h) | I4: Daily demand (t) | J4: Notes
A5: M01 | B5: Kawran Bazar | C5: Nearby shops | D5: 3 | E5: Local | F5: None | G5: 0 | H5: 0 | I5: 3 | J5: Pedal van market runs.
A6: M02 | B6: Dhaka | C6: Neighbourhood delivery | D6: 8 | E6: Local | F6: None | G6: 0 | H6: 0.2 | I6: 8 | J6: Battery cargo, parcels.
A7: R01 | B7: Dhaka (Tejgaon) | C7: Dhaka city | D7: 15 | E7: Local | F7: None | G7: 0 | H7: 0.3 | I7: 60 | J7: Starter route. Two pickups use up most of the demand.
A8: R02 | B8: Dhaka | C8: Narayanganj | D8: 20 | E8: Local | F8: None | G8: 0 | H8: 0.3 | I8: 50
A9: R03 | B9: Dhaka | C9: Gazipur | D9: 35 | E9: Local | F9: None | G9: 0 | H9: 0.5 | I9: 80 | J9: Garment belt.
A10: R04 | B10: Dhaka | C10: Cumilla | D10: 100 | E10: Line | F10: Meghna+Gumti | G10: 1 | H10: 0.5 | I10: 120
A11: R05 | B11: Dhaka | C11: Chattogram Port | D11: 250 | E11: Line | F11: Meghna+Gumti | G11: 2 | H11: 1 | I11: 400 | J11: N1, the main trade corridor.
A12: R06 | B12: Gazipur | C12: Chattogram Port | D12: 280 | E12: Line | F12: Meghna+Gumti | G12: 2 | H12: 1.5 | I12: 300 | J12: Garment exports.
A13: R07 | B13: Dhaka | C13: Sylhet | D13: 240 | E13: Line | F13: None | G13: 0 | H13: 0.5 | I13: 100
A14: R08 | B14: Dhaka | C14: Bogura | D14: 200 | E14: Line | F14: Jamuna Bridge | G14: 1 | H14: 0.5 | I14: 150 | J14: Northern farm goods.
A15: R09 | B15: Dhaka | C15: Rangpur | D15: 300 | E15: Line | F15: Jamuna Bridge | G15: 1 | H15: 0.5 | I15: 100
A16: R10 | B16: Dhaka | C16: Khulna (via Padma) | D16: 220 | E16: Line | F16: Padma Bridge | G16: 0 | H16: 0.5 | I16: 120 | J16: Fish and shrimp belt.
A17: R11 | B17: Dhaka | C17: Khulna (via Paturia ferry) | D17: 270 | E17: Line | F17: Paturia Ferry | G17: 0 | H17: 6 | I17: 120 | J17: Cheaper toll, average 6 h ferry wait (can be 2 to 48 h).
A18: R12 | B18: Dhaka | C18: Benapole | D18: 200 | E18: Line | F18: Padma Bridge | G18: 0 | H18: 2 | I18: 150 | J18: India border, queue at the land port.
A19: R13 | B19: Chattogram Port | C19: Cumilla | D19: 150 | E19: Line | F19: None | G19: 1 | H19: 0.5 | I19: 100
A20: R14 | B20: Narayanganj | C20: Dhaka sites (sand) | D20: 25 | E20: Local | F20: None | G20: 0 | H20: 0.5 | I20: 200 | J20: Tipper loop.

Sheet Trip Calculator
A1: Trip calculator: one row per scenario
A2: Change the blue columns (tier, route, cargo, overload). Everything else is calculated. Payback assumes the vehicle is always busy at 1x speed.
A4: Scenario | B4: Tier | C4: Route ID | D4: Cargo | E4: Overload asked (t) | F4: Vehicle | G4: Price (Tk) | H4: Legal payload (t) | I4: Load carried (t) | J4: Overload ratio | K4: Haul type | L4: One-way km | M4: Driven km | N4: Revenue (Tk) | O4: Energy (Tk) | P4: Tolls (Tk) | Q4: Trip time (game h) | R4: Crew (Tk) | S4: Maintenance (Tk) | T4: Expected fines (Tk) | U4: Expected accident cost (Tk) | V4: Total cost (Tk) | W4: Profit per trip (Tk) | X4: Margin | Y4: Trip time (real min at 1x) | Z4: Profit per real hour (Tk) | AA4: Payback (real h) | AB4: Target (real h) | AC4: Status | AD4: Trips per game day | AE4: Vehicles before demand runs out | AF4: Warning
A5: Tier 1 typical | B5: 1 | C5: M01 | D5: Market goods | E5: 0 | F5: =INDEX(Vehicles!$B$5:$B$16,MATCH($B5,Vehicles!$A$5:$A$16,0)) -> Sonar Van | G5: =INDEX(Vehicles!$E$5:$E$16,MATCH($B5,Vehicles!$A$5:$A$16,0)) -> 20000 | H5: =INDEX(Vehicles!$F$5:$F$16,MATCH($B5,Vehicles!$A$5:$A$16,0)) -> 0.3 | I5: =H5+MAX(0,MIN(E5,INDEX(Vehicles!$G$5:$G$16,MATCH($B5,Vehicles!$A$5:$A$16,0))-H5)) -> 0.3 | J5: =(I5-H5)/H5 -> 0 | K5: =INDEX(Routes!$E$5:$E$20,MATCH($C5,Routes!$A$5:$A$20,0)) -> Local | L5: =INDEX(Routes!$D$5:$D$20,MATCH($C5,Routes!$A$5:$A$20,0)) -> 3 | M5: =IF(K5="Local",2*L5,L5) -> 6 | N5: =I5*(Settings!$B$6+Settings!$B$7*L5)*INDEX(Cargo!$B$4:$B$15,MATCH($D5,Cargo!$A$4:$A$15,0))*INDEX(Vehicles!$O$5:$O$16,MATCH($B5,Vehicles!$A$5:$A$16,0))*Settings!$B$8 -> 439.425 | O5: =M5*INDEX(Vehicles!$K$5:$K$16,MATCH($B5,Vehicles!$A$5:$A$16,0))*(1+Settings!$B$18*J5) -> 0 | P5: =INDEX(Tolls!$B$5:$F$11,MATCH(INDEX(Vehicles!$P$5:$P$16,MATCH($B5,Vehicles!$A$5:$A$16,0)),Tolls!$A$5:$A$11,0),MATCH(INDEX(Routes!$F$5:$F$20,MATCH($C5,Routes!$A$5:$A$20,0)),Tolls!$B$4:$F$4,0))*IF(K5="Local",2,1) -> 0 | Q5: =M5/INDEX(Vehicles!$H$5:$H$16,MATCH($B5,Vehicles!$A$5:$A$16,0))+INDEX(Vehicles!$N$5:$N$16,MATCH($B5,Vehicles!$A$5:$A$16,0))+INDEX(Routes!$H$5:$H$20,MATCH($C5,Routes!$A$5:$A$20,0)) -> 1.05 | R5: =Q5*INDEX(Vehicles!$M$5:$M$16,MATCH($B5,Vehicles!$A$5:$A$16,0)) -> 52.5 | S5: =M5*INDEX(Vehicles!$L$5:$L$16,MATCH($B5,Vehicles!$A$5:$A$16,0))*(1+Settings!$B$19*J5) -> 1.2 | T5: =IF(I5>H5,INDEX(Routes!$G$5:$G$20,MATCH($C5,Routes!$A$5:$A$20,0))*Settings!$B$20*(Settings!$B$21+Settings!$B$22*(I5-H5)),0) -> 0 | U5: =G5*Settings!$B$23*M5/100*(1+Settings!$B$24*J5)*Settings!$B$25 -> 0.24 | V5: =SUM(O5:P5)+SUM(R5:U5) -> 53.94 | W5: =N5-V5 -> 385.485 | X5: =IF(N5>0,W5/N5,0) -> 0.87724868 | Y5: =Q5*60/Settings!$B$9 -> 1.05 | Z5: =IF(Y5>0,W5/Y5*60,0) -> 22027.714 | AA5: =IF(Z5>0,G5/Z5,"Never") -> 0.90794713 | AB5: =INDEX(Vehicles!$S$5:$S$16,MATCH($B5,Vehicles!$A$5:$A$16,0))&" to "&INDEX(Vehicles!$T$5:$T$16,MATCH($B5,Vehicles!$A$5:$A$16,0)) -> 0.5 to 5 | AC5: =IF(NOT(ISNUMBER(AA5)),"Loses money",IF(AA5<INDEX(Vehicles!$S$5:$S$16,MATCH($B5,Vehicles!$A$5:$A$16,0)),"Too fast",IF(AA5>INDEX(Vehicles!$T$5:$T$16,MATCH($B5,Vehicles!$A$5:$A$16,0)),"Too slow","OK"))) -> OK | AD5: =24/Q5 -> 22.857143 | AE5: =INDEX(Routes!$I$5:$I$20,MATCH($C5,Routes!$A$5:$A$20,0))/(I5*AD5) -> 0.4375 | AF5: =IF(AND(INDEX(Vehicles!$Q$5:$Q$16,MATCH($B5,Vehicles!$A$5:$A$16,0))="No",K5="Line"),"Not allowed on highway",IF(AND(K5="Line",L5>Settings!$B$26),"Line haul too long",IF(ISERROR(SEARCH(","&B5&",",","&INDEX(Cargo!$C$4:$C$15,MATCH($D5,Cargo!$A$4:$A$15,0))&",")),"Cargo not allowed on this vehicle","")))
A6: Tier 2 typical | B6: 2 | C6: M02 | D6: Parcels | E6: 0 | F6: =INDEX(Vehicles!$B$5:$B$16,MATCH($B6,Vehicles!$A$5:$A$16,0)) -> Bijli Cargo | G6: =INDEX(Vehicles!$E$5:$E$16,MATCH($B6,Vehicles!$A$5:$A$16,0)) -> 150000 | H6: =INDEX(Vehicles!$F$5:$F$16,MATCH($B6,Vehicles!$A$5:$A$16,0)) -> 0.5 | I6: =H6+MAX(0,MIN(E6,INDEX(Vehicles!$G$5:$G$16,MATCH($B6,Vehicles!$A$5:$A$16,0))-H6)) -> 0.5 | J6: =(I6-H6)/H6 -> 0 | K6: =INDEX(Routes!$E$5:$E$20,MATCH($C6,Routes!$A$5:$A$20,0)) -> Local | L6: =INDEX(Routes!$D$5:$D$20,MATCH($C6,Routes!$A$5:$A$20,0)) -> 8 | M6: =IF(K6="Local",2*L6,L6) -> 16 | N6: =I6*(Settings!$B$6+Settings!$B$7*L6)*INDEX(Cargo!$B$4:$B$15,MATCH($D6,Cargo!$A$4:$A$15,0))*INDEX(Vehicles!$O$5:$O$16,MATCH($B6,Vehicles!$A$5:$A$16,0))*Settings!$B$8 -> 1117.8 | O6: =M6*INDEX(Vehicles!$K$5:$K$16,MATCH($B6,Vehicles!$A$5:$A$16,0))*(1+Settings!$B$18*J6) -> 24 | P6: =INDEX(Tolls!$B$5:$F$11,MATCH(INDEX(Vehicles!$P$5:$P$16,MATCH($B6,Vehicles!$A$5:$A$16,0)),Tolls!$A$5:$A$11,0),MATCH(INDEX(Routes!$F$5:$F$20,MATCH($C6,Routes!$A$5:$A$20,0)),Tolls!$B$4:$F$4,0))*IF(K6="Local",2,1) -> 0 | Q6: =M6/INDEX(Vehicles!$H$5:$H$16,MATCH($B6,Vehicles!$A$5:$A$16,0))+INDEX(Vehicles!$N$5:$N$16,MATCH($B6,Vehicles!$A$5:$A$16,0))+INDEX(Routes!$H$5:$H$20,MATCH($C6,Routes!$A$5:$A$20,0)) -> 1.3 | R6: =Q6*INDEX(Vehicles!$M$5:$M$16,MATCH($B6,Vehicles!$A$5:$A$16,0)) -> 78 | S6: =M6*INDEX(Vehicles!$L$5:$L$16,MATCH($B6,Vehicles!$A$5:$A$16,0))*(1+Settings!$B$19*J6) -> 8 | T6: =IF(I6>H6,INDEX(Routes!$G$5:$G$20,MATCH($C6,Routes!$A$5:$A$20,0))*Settings!$B$20*(Settings!$B$21+Settings!$B$22*(I6-H6)),0) -> 0 | U6: =G6*Settings!$B$23*M6/100*(1+Settings!$B$24*J6)*Settings!$B$25 -> 4.8 | V6: =SUM(O6:P6)+SUM(R6:U6) -> 114.8 | W6: =N6-V6 -> 1003 | X6: =IF(N6>0,W6/N6,0) -> 0.89729826 | Y6: =Q6*60/Settings!$B$9 -> 1.3 | Z6: =IF(Y6>0,W6/Y6*60,0) -> 46292.308 | AA6: =IF(Z6>0,G6/Z6,"Never") -> 3.2402792 | AB6: =INDEX(Vehicles!$S$5:$S$16,MATCH($B6,Vehicles!$A$5:$A$16,0))&" to "&INDEX(Vehicles!$T$5:$T$16,MATCH($B6,Vehicles!$A$5:$A$16,0)) -> 1 to 10 | AC6: =IF(NOT(ISNUMBER(AA6)),"Loses money",IF(AA6<INDEX(Vehicles!$S$5:$S$16,MATCH($B6,Vehicles!$A$5:$A$16,0)),"Too fast",IF(AA6>INDEX(Vehicles!$T$5:$T$16,MATCH($B6,Vehicles!$A$5:$A$16,0)),"Too slow","OK"))) -> OK | AD6: =24/Q6 -> 18.461538 | AE6: =INDEX(Routes!$I$5:$I$20,MATCH($C6,Routes!$A$5:$A$20,0))/(I6*AD6) -> 0.86666667 | AF6: =IF(AND(INDEX(Vehicles!$Q$5:$Q$16,MATCH($B6,Vehicles!$A$5:$A$16,0))="No",K6="Line"),"Not allowed on highway",IF(AND(K6="Line",L6>Settings!$B$26),"Line haul too long",IF(ISERROR(SEARCH(","&B6&",",","&INDEX(Cargo!$C$4:$C$15,MATCH($D6,Cargo!$A$4:$A$15,0))&",")),"Cargo not allowed on this vehicle","")))
A7: Tier 3 typical | B7: 3 | C7: R01 | D7: Parcels | E7: 0 | F7: =INDEX(Vehicles!$B$5:$B$16,MATCH($B7,Vehicles!$A$5:$A$16,0)) -> Tuntuni Mini | G7: =INDEX(Vehicles!$E$5:$E$16,MATCH($B7,Vehicles!$A$5:$A$16,0)) -> 1000000 | H7: =INDEX(Vehicles!$F$5:$F$16,MATCH($B7,Vehicles!$A$5:$A$16,0)) -> 0.8 | I7: =H7+MAX(0,MIN(E7,INDEX(Vehicles!$G$5:$G$16,MATCH($B7,Vehicles!$A$5:$A$16,0))-H7)) -> 0.8 | J7: =(I7-H7)/H7 -> 0 | K7: =INDEX(Routes!$E$5:$E$20,MATCH($C7,Routes!$A$5:$A$20,0)) -> Local | L7: =INDEX(Routes!$D$5:$D$20,MATCH($C7,Routes!$A$5:$A$20,0)) -> 15 | M7: =IF(K7="Local",2*L7,L7) -> 30 | N7: =I7*(Settings!$B$6+Settings!$B$7*L7)*INDEX(Cargo!$B$4:$B$15,MATCH($D7,Cargo!$A$4:$A$15,0))*INDEX(Vehicles!$O$5:$O$16,MATCH($B7,Vehicles!$A$5:$A$16,0))*Settings!$B$8 -> 2308.5 | O7: =M7*INDEX(Vehicles!$K$5:$K$16,MATCH($B7,Vehicles!$A$5:$A$16,0))*(1+Settings!$B$18*J7) -> 270 | P7: =INDEX(Tolls!$B$5:$F$11,MATCH(INDEX(Vehicles!$P$5:$P$16,MATCH($B7,Vehicles!$A$5:$A$16,0)),Tolls!$A$5:$A$11,0),MATCH(INDEX(Routes!$F$5:$F$20,MATCH($C7,Routes!$A$5:$A$20,0)),Tolls!$B$4:$F$4,0))*IF(K7="Local",2,1) -> 0 | Q7: =M7/INDEX(Vehicles!$H$5:$H$16,MATCH($B7,Vehicles!$A$5:$A$16,0))+INDEX(Vehicles!$N$5:$N$16,MATCH($B7,Vehicles!$A$5:$A$16,0))+INDEX(Routes!$H$5:$H$20,MATCH($C7,Routes!$A$5:$A$20,0)) -> 1.4666667 | R7: =Q7*INDEX(Vehicles!$M$5:$M$16,MATCH($B7,Vehicles!$A$5:$A$16,0)) -> 102.66667 | S7: =M7*INDEX(Vehicles!$L$5:$L$16,MATCH($B7,Vehicles!$A$5:$A$16,0))*(1+Settings!$B$19*J7) -> 45 | T7: =IF(I7>H7,INDEX(Routes!$G$5:$G$20,MATCH($C7,Routes!$A$5:$A$20,0))*Settings!$B$20*(Settings!$B$21+Settings!$B$22*(I7-H7)),0) -> 0 | U7: =G7*Settings!$B$23*M7/100*(1+Settings!$B$24*J7)*Settings!$B$25 -> 60 | V7: =SUM(O7:P7)+SUM(R7:U7) -> 477.66667 | W7: =N7-V7 -> 1830.8333 | X7: =IF(N7>0,W7/N7,0) -> 0.79308353 | Y7: =Q7*60/Settings!$B$9 -> 1.4666667 | Z7: =IF(Y7>0,W7/Y7*60,0) -> 74897.727 | AA7: =IF(Z7>0,G7/Z7,"Never") -> 13.35154 | AB7: =INDEX(Vehicles!$S$5:$S$16,MATCH($B7,Vehicles!$A$5:$A$16,0))&" to "&INDEX(Vehicles!$T$5:$T$16,MATCH($B7,Vehicles!$A$5:$A$16,0)) -> 5 to 30 | AC7: =IF(NOT(ISNUMBER(AA7)),"Loses money",IF(AA7<INDEX(Vehicles!$S$5:$S$16,MATCH($B7,Vehicles!$A$5:$A$16,0)),"Too fast",IF(AA7>INDEX(Vehicles!$T$5:$T$16,MATCH($B7,Vehicles!$A$5:$A$16,0)),"Too slow","OK"))) -> OK | AD7: =24/Q7 -> 16.363636 | AE7: =INDEX(Routes!$I$5:$I$20,MATCH($C7,Routes!$A$5:$A$20,0))/(I7*AD7) -> 4.5833333 | AF7: =IF(AND(INDEX(Vehicles!$Q$5:$Q$16,MATCH($B7,Vehicles!$A$5:$A$16,0))="No",K7="Line"),"Not allowed on highway",IF(AND(K7="Line",L7>Settings!$B$26),"Line haul too long",IF(ISERROR(SEARCH(","&B7&",",","&INDEX(Cargo!$C$4:$C$15,MATCH($D7,Cargo!$A$4:$A$15,0))&",")),"Cargo not allowed on this vehicle","")))
A8: Tier 4 typical (starter) | B8: 4 | C8: R01 | D8: General dry | E8: 0 | F8: =INDEX(Vehicles!$B$5:$B$16,MATCH($B8,Vehicles!$A$5:$A$16,0)) -> Sathi Plus | G8: =INDEX(Vehicles!$E$5:$E$16,MATCH($B8,Vehicles!$A$5:$A$16,0)) -> 1300000 | H8: =INDEX(Vehicles!$F$5:$F$16,MATCH($B8,Vehicles!$A$5:$A$16,0)) -> 1.5 | I8: =H8+MAX(0,MIN(E8,INDEX(Vehicles!$G$5:$G$16,MATCH($B8,Vehicles!$A$5:$A$16,0))-H8)) -> 1.5 | J8: =(I8-H8)/H8 -> 0 | K8: =INDEX(Routes!$E$5:$E$20,MATCH($C8,Routes!$A$5:$A$20,0)) -> Local | L8: =INDEX(Routes!$D$5:$D$20,MATCH($C8,Routes!$A$5:$A$20,0)) -> 15 | M8: =IF(K8="Local",2*L8,L8) -> 30 | N8: =I8*(Settings!$B$6+Settings!$B$7*L8)*INDEX(Cargo!$B$4:$B$15,MATCH($D8,Cargo!$A$4:$A$15,0))*INDEX(Vehicles!$O$5:$O$16,MATCH($B8,Vehicles!$A$5:$A$16,0))*Settings!$B$8 -> 2693.25 | O8: =M8*INDEX(Vehicles!$K$5:$K$16,MATCH($B8,Vehicles!$A$5:$A$16,0))*(1+Settings!$B$18*J8) -> 337.5 | P8: =INDEX(Tolls!$B$5:$F$11,MATCH(INDEX(Vehicles!$P$5:$P$16,MATCH($B8,Vehicles!$A$5:$A$16,0)),Tolls!$A$5:$A$11,0),MATCH(INDEX(Routes!$F$5:$F$20,MATCH($C8,Routes!$A$5:$A$20,0)),Tolls!$B$4:$F$4,0))*IF(K8="Local",2,1) -> 0 | Q8: =M8/INDEX(Vehicles!$H$5:$H$16,MATCH($B8,Vehicles!$A$5:$A$16,0))+INDEX(Vehicles!$N$5:$N$16,MATCH($B8,Vehicles!$A$5:$A$16,0))+INDEX(Routes!$H$5:$H$20,MATCH($C8,Routes!$A$5:$A$20,0)) -> 1.4 | R8: =Q8*INDEX(Vehicles!$M$5:$M$16,MATCH($B8,Vehicles!$A$5:$A$16,0)) -> 112 | S8: =M8*INDEX(Vehicles!$L$5:$L$16,MATCH($B8,Vehicles!$A$5:$A$16,0))*(1+Settings!$B$19*J8) -> 60 | T8: =IF(I8>H8,INDEX(Routes!$G$5:$G$20,MATCH($C8,Routes!$A$5:$A$20,0))*Settings!$B$20*(Settings!$B$21+Settings!$B$22*(I8-H8)),0) -> 0 | U8: =G8*Settings!$B$23*M8/100*(1+Settings!$B$24*J8)*Settings!$B$25 -> 78 | V8: =SUM(O8:P8)+SUM(R8:U8) -> 587.5 | W8: =N8-V8 -> 2105.75 | X8: =IF(N8>0,W8/N8,0) -> 0.78186206 | Y8: =Q8*60/Settings!$B$9 -> 1.4 | Z8: =IF(Y8>0,W8/Y8*60,0) -> 90246.429 | AA8: =IF(Z8>0,G8/Z8,"Never") -> 14.405002 | AB8: =INDEX(Vehicles!$S$5:$S$16,MATCH($B8,Vehicles!$A$5:$A$16,0))&" to "&INDEX(Vehicles!$T$5:$T$16,MATCH($B8,Vehicles!$A$5:$A$16,0)) -> 5 to 30 | AC8: =IF(NOT(ISNUMBER(AA8)),"Loses money",IF(AA8<INDEX(Vehicles!$S$5:$S$16,MATCH($B8,Vehicles!$A$5:$A$16,0)),"Too fast",IF(AA8>INDEX(Vehicles!$T$5:$T$16,MATCH($B8,Vehicles!$A$5:$A$16,0)),"Too slow","OK"))) -> OK | AD8: =24/Q8 -> 17.142857 | AE8: =INDEX(Routes!$I$5:$I$20,MATCH($C8,Routes!$A$5:$A$20,0))/(I8*AD8) -> 2.3333333 | AF8: =IF(AND(INDEX(Vehicles!$Q$5:$Q$16,MATCH($B8,Vehicles!$A$5:$A$16,0))="No",K8="Line"),"Not allowed on highway",IF(AND(K8="Line",L8>Settings!$B$26),"Line haul too long",IF(ISERROR(SEARCH(","&B8&",",","&INDEX(Cargo!$C$4:$C$15,MATCH($D8,Cargo!$A$4:$A$15,0))&",")),"Cargo not allowed on this vehicle","")))
A9: Tier 5 typical | B9: 5 | C9: R04 | D9: Parcels | E9: 0 | F9: =INDEX(Vehicles!$B$5:$B$16,MATCH($B9,Vehicles!$A$5:$A$16,0)) -> Meghna 14 | G9: =INDEX(Vehicles!$E$5:$E$16,MATCH($B9,Vehicles!$A$5:$A$16,0)) -> 2500000 | H9: =INDEX(Vehicles!$F$5:$F$16,MATCH($B9,Vehicles!$A$5:$A$16,0)) -> 4 | I9: =H9+MAX(0,MIN(E9,INDEX(Vehicles!$G$5:$G$16,MATCH($B9,Vehicles!$A$5:$A$16,0))-H9)) -> 4 | J9: =(I9-H9)/H9 -> 0 | K9: =INDEX(Routes!$E$5:$E$20,MATCH($C9,Routes!$A$5:$A$20,0)) -> Line | L9: =INDEX(Routes!$D$5:$D$20,MATCH($C9,Routes!$A$5:$A$20,0)) -> 100 | M9: =IF(K9="Local",2*L9,L9) -> 100 | N9: =I9*(Settings!$B$6+Settings!$B$7*L9)*INDEX(Cargo!$B$4:$B$15,MATCH($D9,Cargo!$A$4:$A$15,0))*INDEX(Vehicles!$O$5:$O$16,MATCH($B9,Vehicles!$A$5:$A$16,0))*Settings!$B$8 -> 16560 | O9: =M9*INDEX(Vehicles!$K$5:$K$16,MATCH($B9,Vehicles!$A$5:$A$16,0))*(1+Settings!$B$18*J9) -> 1687.5 | P9: =INDEX(Tolls!$B$5:$F$11,MATCH(INDEX(Vehicles!$P$5:$P$16,MATCH($B9,Vehicles!$A$5:$A$16,0)),Tolls!$A$5:$A$11,0),MATCH(INDEX(Routes!$F$5:$F$20,MATCH($C9,Routes!$A$5:$A$20,0)),Tolls!$B$4:$F$4,0))*IF(K9="Local",2,1) -> 500 | Q9: =M9/INDEX(Vehicles!$H$5:$H$16,MATCH($B9,Vehicles!$A$5:$A$16,0))+INDEX(Vehicles!$N$5:$N$16,MATCH($B9,Vehicles!$A$5:$A$16,0))+INDEX(Routes!$H$5:$H$20,MATCH($C9,Routes!$A$5:$A$20,0)) -> 3.7222222 | R9: =Q9*INDEX(Vehicles!$M$5:$M$16,MATCH($B9,Vehicles!$A$5:$A$16,0)) -> 409.44444 | S9: =M9*INDEX(Vehicles!$L$5:$L$16,MATCH($B9,Vehicles!$A$5:$A$16,0))*(1+Settings!$B$19*J9) -> 300 | T9: =IF(I9>H9,INDEX(Routes!$G$5:$G$20,MATCH($C9,Routes!$A$5:$A$20,0))*Settings!$B$20*(Settings!$B$21+Settings!$B$22*(I9-H9)),0) -> 0 | U9: =G9*Settings!$B$23*M9/100*(1+Settings!$B$24*J9)*Settings!$B$25 -> 500 | V9: =SUM(O9:P9)+SUM(R9:U9) -> 3396.9444 | W9: =N9-V9 -> 13163.056 | X9: =IF(N9>0,W9/N9,0) -> 0.7948705 | Y9: =Q9*60/Settings!$B$9 -> 3.7222222 | Z9: =IF(Y9>0,W9/Y9*60,0) -> 212180.6 | AA9: =IF(Z9>0,G9/Z9,"Never") -> 11.782416 | AB9: =INDEX(Vehicles!$S$5:$S$16,MATCH($B9,Vehicles!$A$5:$A$16,0))&" to "&INDEX(Vehicles!$T$5:$T$16,MATCH($B9,Vehicles!$A$5:$A$16,0)) -> 10 to 40 | AC9: =IF(NOT(ISNUMBER(AA9)),"Loses money",IF(AA9<INDEX(Vehicles!$S$5:$S$16,MATCH($B9,Vehicles!$A$5:$A$16,0)),"Too fast",IF(AA9>INDEX(Vehicles!$T$5:$T$16,MATCH($B9,Vehicles!$A$5:$A$16,0)),"Too slow","OK"))) -> OK | AD9: =24/Q9 -> 6.4477612 | AE9: =INDEX(Routes!$I$5:$I$20,MATCH($C9,Routes!$A$5:$A$20,0))/(I9*AD9) -> 4.6527778 | AF9: =IF(AND(INDEX(Vehicles!$Q$5:$Q$16,MATCH($B9,Vehicles!$A$5:$A$16,0))="No",K9="Line"),"Not allowed on highway",IF(AND(K9="Line",L9>Settings!$B$26),"Line haul too long",IF(ISERROR(SEARCH(","&B9&",",","&INDEX(Cargo!$C$4:$C$15,MATCH($D9,Cargo!$A$4:$A$15,0))&",")),"Cargo not allowed on this vehicle","")))
A10: Tier 6 typical | B10: 6 | C10: R05 | D10: General dry | E10: 0 | F10: =INDEX(Vehicles!$B$5:$B$16,MATCH($B10,Vehicles!$A$5:$A$16,0)) -> Jamuna Open | G10: =INDEX(Vehicles!$E$5:$E$16,MATCH($B10,Vehicles!$A$5:$A$16,0)) -> 3200000 | H10: =INDEX(Vehicles!$F$5:$F$16,MATCH($B10,Vehicles!$A$5:$A$16,0)) -> 10 | I10: =H10+MAX(0,MIN(E10,INDEX(Vehicles!$G$5:$G$16,MATCH($B10,Vehicles!$A$5:$A$16,0))-H10)) -> 10 | J10: =(I10-H10)/H10 -> 0 | K10: =INDEX(Routes!$E$5:$E$20,MATCH($C10,Routes!$A$5:$A$20,0)) -> Line | L10: =INDEX(Routes!$D$5:$D$20,MATCH($C10,Routes!$A$5:$A$20,0)) -> 250 | M10: =IF(K10="Local",2*L10,L10) -> 250 | N10: =I10*(Settings!$B$6+Settings!$B$7*L10)*INDEX(Cargo!$B$4:$B$15,MATCH($D10,Cargo!$A$4:$A$15,0))*INDEX(Vehicles!$O$5:$O$16,MATCH($B10,Vehicles!$A$5:$A$16,0))*Settings!$B$8 -> 36375 | O10: =M10*INDEX(Vehicles!$K$5:$K$16,MATCH($B10,Vehicles!$A$5:$A$16,0))*(1+Settings!$B$18*J10) -> 7500 | P10: =INDEX(Tolls!$B$5:$F$11,MATCH(INDEX(Vehicles!$P$5:$P$16,MATCH($B10,Vehicles!$A$5:$A$16,0)),Tolls!$A$5:$A$11,0),MATCH(INDEX(Routes!$F$5:$F$20,MATCH($C10,Routes!$A$5:$A$20,0)),Tolls!$B$4:$F$4,0))*IF(K10="Local",2,1) -> 800 | Q10: =M10/INDEX(Vehicles!$H$5:$H$16,MATCH($B10,Vehicles!$A$5:$A$16,0))+INDEX(Vehicles!$N$5:$N$16,MATCH($B10,Vehicles!$A$5:$A$16,0))+INDEX(Routes!$H$5:$H$20,MATCH($C10,Routes!$A$5:$A$20,0)) -> 9.25 | R10: =Q10*INDEX(Vehicles!$M$5:$M$16,MATCH($B10,Vehicles!$A$5:$A$16,0)) -> 1480 | S10: =M10*INDEX(Vehicles!$L$5:$L$16,MATCH($B10,Vehicles!$A$5:$A$16,0))*(1+Settings!$B$19*J10) -> 1000 | T10: =IF(I10>H10,INDEX(Routes!$G$5:$G$20,MATCH($C10,Routes!$A$5:$A$20,0))*Settings!$B$20*(Settings!$B$21+Settings!$B$22*(I10-H10)),0) -> 0 | U10: =G10*Settings!$B$23*M10/100*(1+Settings!$B$24*J10)*Settings!$B$25 -> 1600 | V10: =SUM(O10:P10)+SUM(R10:U10) -> 12380 | W10: =N10-V10 -> 23995 | X10: =IF(N10>0,W10/N10,0) -> 0.65965636 | Y10: =Q10*60/Settings!$B$9 -> 9.25 | Z10: =IF(Y10>0,W10/Y10*60,0) -> 155643.24 | AA10: =IF(Z10>0,G10/Z10,"Never") -> 20.559839 | AB10: =INDEX(Vehicles!$S$5:$S$16,MATCH($B10,Vehicles!$A$5:$A$16,0))&" to "&INDEX(Vehicles!$T$5:$T$16,MATCH($B10,Vehicles!$A$5:$A$16,0)) -> 10 to 40 | AC10: =IF(NOT(ISNUMBER(AA10)),"Loses money",IF(AA10<INDEX(Vehicles!$S$5:$S$16,MATCH($B10,Vehicles!$A$5:$A$16,0)),"Too fast",IF(AA10>INDEX(Vehicles!$T$5:$T$16,MATCH($B10,Vehicles!$A$5:$A$16,0)),"Too slow","OK"))) -> OK | AD10: =24/Q10 -> 2.5945946 | AE10: =INDEX(Routes!$I$5:$I$20,MATCH($C10,Routes!$A$5:$A$20,0))/(I10*AD10) -> 15.416667 | AF10: =IF(AND(INDEX(Vehicles!$Q$5:$Q$16,MATCH($B10,Vehicles!$A$5:$A$16,0))="No",K10="Line"),"Not allowed on highway",IF(AND(K10="Line",L10>Settings!$B$26),"Line haul too long",IF(ISERROR(SEARCH(","&B10&",",","&INDEX(Cargo!$C$4:$C$15,MATCH($D10,Cargo!$A$4:$A$15,0))&",")),"Cargo not allowed on this vehicle","")))
A11: Tier 7 typical | B11: 7 | C11: R06 | D11: Garments | E11: 0 | F11: =INDEX(Vehicles!$B$5:$B$16,MATCH($B11,Vehicles!$A$5:$A$16,0)) -> Karnaphuli 20 | G11: =INDEX(Vehicles!$E$5:$E$16,MATCH($B11,Vehicles!$A$5:$A$16,0)) -> 3500000 | H11: =INDEX(Vehicles!$F$5:$F$16,MATCH($B11,Vehicles!$A$5:$A$16,0)) -> 10 | I11: =H11+MAX(0,MIN(E11,INDEX(Vehicles!$G$5:$G$16,MATCH($B11,Vehicles!$A$5:$A$16,0))-H11)) -> 10 | J11: =(I11-H11)/H11 -> 0 | K11: =INDEX(Routes!$E$5:$E$20,MATCH($C11,Routes!$A$5:$A$20,0)) -> Line | L11: =INDEX(Routes!$D$5:$D$20,MATCH($C11,Routes!$A$5:$A$20,0)) -> 280 | M11: =IF(K11="Local",2*L11,L11) -> 280 | N11: =I11*(Settings!$B$6+Settings!$B$7*L11)*INDEX(Cargo!$B$4:$B$15,MATCH($D11,Cargo!$A$4:$A$15,0))*INDEX(Vehicles!$O$5:$O$16,MATCH($B11,Vehicles!$A$5:$A$16,0))*Settings!$B$8 -> 59094 | O11: =M11*INDEX(Vehicles!$K$5:$K$16,MATCH($B11,Vehicles!$A$5:$A$16,0))*(1+Settings!$B$18*J11) -> 8400 | P11: =INDEX(Tolls!$B$5:$F$11,MATCH(INDEX(Vehicles!$P$5:$P$16,MATCH($B11,Vehicles!$A$5:$A$16,0)),Tolls!$A$5:$A$11,0),MATCH(INDEX(Routes!$F$5:$F$20,MATCH($C11,Routes!$A$5:$A$20,0)),Tolls!$B$4:$F$4,0))*IF(K11="Local",2,1) -> 800 | Q11: =M11/INDEX(Vehicles!$H$5:$H$16,MATCH($B11,Vehicles!$A$5:$A$16,0))+INDEX(Vehicles!$N$5:$N$16,MATCH($B11,Vehicles!$A$5:$A$16,0))+INDEX(Routes!$H$5:$H$20,MATCH($C11,Routes!$A$5:$A$20,0)) -> 10.5 | R11: =Q11*INDEX(Vehicles!$M$5:$M$16,MATCH($B11,Vehicles!$A$5:$A$16,0)) -> 1680 | S11: =M11*INDEX(Vehicles!$L$5:$L$16,MATCH($B11,Vehicles!$A$5:$A$16,0))*(1+Settings!$B$19*J11) -> 1260 | T11: =IF(I11>H11,INDEX(Routes!$G$5:$G$20,MATCH($C11,Routes!$A$5:$A$20,0))*Settings!$B$20*(Settings!$B$21+Settings!$B$22*(I11-H11)),0) -> 0 | U11: =G11*Settings!$B$23*M11/100*(1+Settings!$B$24*J11)*Settings!$B$25 -> 1960 | V11: =SUM(O11:P11)+SUM(R11:U11) -> 14100 | W11: =N11-V11 -> 44994 | X11: =IF(N11>0,W11/N11,0) -> 0.7613971 | Y11: =Q11*60/Settings!$B$9 -> 10.5 | Z11: =IF(Y11>0,W11/Y11*60,0) -> 257108.57 | AA11: =IF(Z11>0,G11/Z11,"Never") -> 13.612926 | AB11: =INDEX(Vehicles!$S$5:$S$16,MATCH($B11,Vehicles!$A$5:$A$16,0))&" to "&INDEX(Vehicles!$T$5:$T$16,MATCH($B11,Vehicles!$A$5:$A$16,0)) -> 10 to 40 | AC11: =IF(NOT(ISNUMBER(AA11)),"Loses money",IF(AA11<INDEX(Vehicles!$S$5:$S$16,MATCH($B11,Vehicles!$A$5:$A$16,0)),"Too fast",IF(AA11>INDEX(Vehicles!$T$5:$T$16,MATCH($B11,Vehicles!$A$5:$A$16,0)),"Too slow","OK"))) -> OK | AD11: =24/Q11 -> 2.2857143 | AE11: =INDEX(Routes!$I$5:$I$20,MATCH($C11,Routes!$A$5:$A$20,0))/(I11*AD11) -> 13.125 | AF11: =IF(AND(INDEX(Vehicles!$Q$5:$Q$16,MATCH($B11,Vehicles!$A$5:$A$16,0))="No",K11="Line"),"Not allowed on highway",IF(AND(K11="Line",L11>Settings!$B$26),"Line haul too long",IF(ISERROR(SEARCH(","&B11&",",","&INDEX(Cargo!$C$4:$C$15,MATCH($D11,Cargo!$A$4:$A$15,0))&",")),"Cargo not allowed on this vehicle","")))
A12: Tier 8 typical | B12: 8 | C12: R10 | D12: Fish | E12: 0 | F12: =INDEX(Vehicles!$B$5:$B$16,MATCH($B12,Vehicles!$A$5:$A$16,0)) -> Himaloy Reefer | G12: =INDEX(Vehicles!$E$5:$E$16,MATCH($B12,Vehicles!$A$5:$A$16,0)) -> 4500000 | H12: =INDEX(Vehicles!$F$5:$F$16,MATCH($B12,Vehicles!$A$5:$A$16,0)) -> 6 | I12: =H12+MAX(0,MIN(E12,INDEX(Vehicles!$G$5:$G$16,MATCH($B12,Vehicles!$A$5:$A$16,0))-H12)) -> 6 | J12: =(I12-H12)/H12 -> 0 | K12: =INDEX(Routes!$E$5:$E$20,MATCH($C12,Routes!$A$5:$A$20,0)) -> Line | L12: =INDEX(Routes!$D$5:$D$20,MATCH($C12,Routes!$A$5:$A$20,0)) -> 220 | M12: =IF(K12="Local",2*L12,L12) -> 220 | N12: =I12*(Settings!$B$6+Settings!$B$7*L12)*INDEX(Cargo!$B$4:$B$15,MATCH($D12,Cargo!$A$4:$A$15,0))*INDEX(Vehicles!$O$5:$O$16,MATCH($B12,Vehicles!$A$5:$A$16,0))*Settings!$B$8 -> 42966 | O12: =M12*INDEX(Vehicles!$K$5:$K$16,MATCH($B12,Vehicles!$A$5:$A$16,0))*(1+Settings!$B$18*J12) -> 8485.7143 | P12: =INDEX(Tolls!$B$5:$F$11,MATCH(INDEX(Vehicles!$P$5:$P$16,MATCH($B12,Vehicles!$A$5:$A$16,0)),Tolls!$A$5:$A$11,0),MATCH(INDEX(Routes!$F$5:$F$20,MATCH($C12,Routes!$A$5:$A$20,0)),Tolls!$B$4:$F$4,0))*IF(K12="Local",2,1) -> 2800 | Q12: =M12/INDEX(Vehicles!$H$5:$H$16,MATCH($B12,Vehicles!$A$5:$A$16,0))+INDEX(Vehicles!$N$5:$N$16,MATCH($B12,Vehicles!$A$5:$A$16,0))+INDEX(Routes!$H$5:$H$20,MATCH($C12,Routes!$A$5:$A$20,0)) -> 8 | R12: =Q12*INDEX(Vehicles!$M$5:$M$16,MATCH($B12,Vehicles!$A$5:$A$16,0)) -> 1440 | S12: =M12*INDEX(Vehicles!$L$5:$L$16,MATCH($B12,Vehicles!$A$5:$A$16,0))*(1+Settings!$B$19*J12) -> 1320 | T12: =IF(I12>H12,INDEX(Routes!$G$5:$G$20,MATCH($C12,Routes!$A$5:$A$20,0))*Settings!$B$20*(Settings!$B$21+Settings!$B$22*(I12-H12)),0) -> 0 | U12: =G12*Settings!$B$23*M12/100*(1+Settings!$B$24*J12)*Settings!$B$25 -> 1980 | V12: =SUM(O12:P12)+SUM(R12:U12) -> 16025.714 | W12: =N12-V12 -> 26940.286 | X12: =IF(N12>0,W12/N12,0) -> 0.62701405 | Y12: =Q12*60/Settings!$B$9 -> 8 | Z12: =IF(Y12>0,W12/Y12*60,0) -> 202052.14 | AA12: =IF(Z12>0,G12/Z12,"Never") -> 22.271479 | AB12: =INDEX(Vehicles!$S$5:$S$16,MATCH($B12,Vehicles!$A$5:$A$16,0))&" to "&INDEX(Vehicles!$T$5:$T$16,MATCH($B12,Vehicles!$A$5:$A$16,0)) -> 10 to 40 | AC12: =IF(NOT(ISNUMBER(AA12)),"Loses money",IF(AA12<INDEX(Vehicles!$S$5:$S$16,MATCH($B12,Vehicles!$A$5:$A$16,0)),"Too fast",IF(AA12>INDEX(Vehicles!$T$5:$T$16,MATCH($B12,Vehicles!$A$5:$A$16,0)),"Too slow","OK"))) -> OK | AD12: =24/Q12 -> 3 | AE12: =INDEX(Routes!$I$5:$I$20,MATCH($C12,Routes!$A$5:$A$20,0))/(I12*AD12) -> 6.6666667 | AF12: =IF(AND(INDEX(Vehicles!$Q$5:$Q$16,MATCH($B12,Vehicles!$A$5:$A$16,0))="No",K12="Line"),"Not allowed on highway",IF(AND(K12="Line",L12>Settings!$B$26),"Line haul too long",IF(ISERROR(SEARCH(","&B12&",",","&INDEX(Cargo!$C$4:$C$15,MATCH($D12,Cargo!$A$4:$A$15,0))&",")),"Cargo not allowed on this vehicle","")))
A13: Tier 9 typical | B13: 9 | C13: R14 | D13: Sand and stone | E13: 0 | F13: =INDEX(Vehicles!$B$5:$B$16,MATCH($B13,Vehicles!$A$5:$A$16,0)) -> Pahari Tipper | G13: =INDEX(Vehicles!$E$5:$E$16,MATCH($B13,Vehicles!$A$5:$A$16,0)) -> 6000000 | H13: =INDEX(Vehicles!$F$5:$F$16,MATCH($B13,Vehicles!$A$5:$A$16,0)) -> 18 | I13: =H13+MAX(0,MIN(E13,INDEX(Vehicles!$G$5:$G$16,MATCH($B13,Vehicles!$A$5:$A$16,0))-H13)) -> 18 | J13: =(I13-H13)/H13 -> 0 | K13: =INDEX(Routes!$E$5:$E$20,MATCH($C13,Routes!$A$5:$A$20,0)) -> Local | L13: =INDEX(Routes!$D$5:$D$20,MATCH($C13,Routes!$A$5:$A$20,0)) -> 25 | M13: =IF(K13="Local",2*L13,L13) -> 50 | N13: =I13*(Settings!$B$6+Settings!$B$7*L13)*INDEX(Cargo!$B$4:$B$15,MATCH($D13,Cargo!$A$4:$A$15,0))*INDEX(Vehicles!$O$5:$O$16,MATCH($B13,Vehicles!$A$5:$A$16,0))*Settings!$B$8 -> 14944.5 | O13: =M13*INDEX(Vehicles!$K$5:$K$16,MATCH($B13,Vehicles!$A$5:$A$16,0))*(1+Settings!$B$18*J13) -> 2250 | P13: =INDEX(Tolls!$B$5:$F$11,MATCH(INDEX(Vehicles!$P$5:$P$16,MATCH($B13,Vehicles!$A$5:$A$16,0)),Tolls!$A$5:$A$11,0),MATCH(INDEX(Routes!$F$5:$F$20,MATCH($C13,Routes!$A$5:$A$20,0)),Tolls!$B$4:$F$4,0))*IF(K13="Local",2,1) -> 0 | Q13: =M13/INDEX(Vehicles!$H$5:$H$16,MATCH($B13,Vehicles!$A$5:$A$16,0))+INDEX(Vehicles!$N$5:$N$16,MATCH($B13,Vehicles!$A$5:$A$16,0))+INDEX(Routes!$H$5:$H$20,MATCH($C13,Routes!$A$5:$A$20,0)) -> 3.6666667 | R13: =Q13*INDEX(Vehicles!$M$5:$M$16,MATCH($B13,Vehicles!$A$5:$A$16,0)) -> 623.33333 | S13: =M13*INDEX(Vehicles!$L$5:$L$16,MATCH($B13,Vehicles!$A$5:$A$16,0))*(1+Settings!$B$19*J13) -> 350 | T13: =IF(I13>H13,INDEX(Routes!$G$5:$G$20,MATCH($C13,Routes!$A$5:$A$20,0))*Settings!$B$20*(Settings!$B$21+Settings!$B$22*(I13-H13)),0) -> 0 | U13: =G13*Settings!$B$23*M13/100*(1+Settings!$B$24*J13)*Settings!$B$25 -> 600 | V13: =SUM(O13:P13)+SUM(R13:U13) -> 3823.3333 | W13: =N13-V13 -> 11121.167 | X13: =IF(N13>0,W13/N13,0) -> 0.74416452 | Y13: =Q13*60/Settings!$B$9 -> 3.6666667 | Z13: =IF(Y13>0,W13/Y13*60,0) -> 181982.73 | AA13: =IF(Z13>0,G13/Z13,"Never") -> 32.970162 | AB13: =INDEX(Vehicles!$S$5:$S$16,MATCH($B13,Vehicles!$A$5:$A$16,0))&" to "&INDEX(Vehicles!$T$5:$T$16,MATCH($B13,Vehicles!$A$5:$A$16,0)) -> 20 to 80 | AC13: =IF(NOT(ISNUMBER(AA13)),"Loses money",IF(AA13<INDEX(Vehicles!$S$5:$S$16,MATCH($B13,Vehicles!$A$5:$A$16,0)),"Too fast",IF(AA13>INDEX(Vehicles!$T$5:$T$16,MATCH($B13,Vehicles!$A$5:$A$16,0)),"Too slow","OK"))) -> OK | AD13: =24/Q13 -> 6.5454545 | AE13: =INDEX(Routes!$I$5:$I$20,MATCH($C13,Routes!$A$5:$A$20,0))/(I13*AD13) -> 1.6975309 | AF13: =IF(AND(INDEX(Vehicles!$Q$5:$Q$16,MATCH($B13,Vehicles!$A$5:$A$16,0))="No",K13="Line"),"Not allowed on highway",IF(AND(K13="Line",L13>Settings!$B$26),"Line haul too long",IF(ISERROR(SEARCH(","&B13&",",","&INDEX(Cargo!$C$4:$C$15,MATCH($D13,Cargo!$A$4:$A$15,0))&",")),"Cargo not allowed on this vehicle","")))
A14: Tier 10 typical | B14: 10 | C14: R05 | D14: Fuel | E14: 0 | F14: =INDEX(Vehicles!$B$5:$B$16,MATCH($B14,Vehicles!$A$5:$A$16,0)) -> Telrani | G14: =INDEX(Vehicles!$E$5:$E$16,MATCH($B14,Vehicles!$A$5:$A$16,0)) -> 5000000 | H14: =INDEX(Vehicles!$F$5:$F$16,MATCH($B14,Vehicles!$A$5:$A$16,0)) -> 12.75 | I14: =H14+MAX(0,MIN(E14,INDEX(Vehicles!$G$5:$G$16,MATCH($B14,Vehicles!$A$5:$A$16,0))-H14)) -> 12.75 | J14: =(I14-H14)/H14 -> 0 | K14: =INDEX(Routes!$E$5:$E$20,MATCH($C14,Routes!$A$5:$A$20,0)) -> Line | L14: =INDEX(Routes!$D$5:$D$20,MATCH($C14,Routes!$A$5:$A$20,0)) -> 250 | M14: =IF(K14="Local",2*L14,L14) -> 250 | N14: =I14*(Settings!$B$6+Settings!$B$7*L14)*INDEX(Cargo!$B$4:$B$15,MATCH($D14,Cargo!$A$4:$A$15,0))*INDEX(Vehicles!$O$5:$O$16,MATCH($B14,Vehicles!$A$5:$A$16,0))*Settings!$B$8 -> 55653.75 | O14: =M14*INDEX(Vehicles!$K$5:$K$16,MATCH($B14,Vehicles!$A$5:$A$16,0))*(1+Settings!$B$18*J14) -> 9642.8571 | P14: =INDEX(Tolls!$B$5:$F$11,MATCH(INDEX(Vehicles!$P$5:$P$16,MATCH($B14,Vehicles!$A$5:$A$16,0)),Tolls!$A$5:$A$11,0),MATCH(INDEX(Routes!$F$5:$F$20,MATCH($C14,Routes!$A$5:$A$20,0)),Tolls!$B$4:$F$4,0))*IF(K14="Local",2,1) -> 1000 | Q14: =M14/INDEX(Vehicles!$H$5:$H$16,MATCH($B14,Vehicles!$A$5:$A$16,0))+INDEX(Vehicles!$N$5:$N$16,MATCH($B14,Vehicles!$A$5:$A$16,0))+INDEX(Routes!$H$5:$H$20,MATCH($C14,Routes!$A$5:$A$20,0)) -> 9.6428571 | R14: =Q14*INDEX(Vehicles!$M$5:$M$16,MATCH($B14,Vehicles!$A$5:$A$16,0)) -> 1928.5714 | S14: =M14*INDEX(Vehicles!$L$5:$L$16,MATCH($B14,Vehicles!$A$5:$A$16,0))*(1+Settings!$B$19*J14) -> 1500 | T14: =IF(I14>H14,INDEX(Routes!$G$5:$G$20,MATCH($C14,Routes!$A$5:$A$20,0))*Settings!$B$20*(Settings!$B$21+Settings!$B$22*(I14-H14)),0) -> 0 | U14: =G14*Settings!$B$23*M14/100*(1+Settings!$B$24*J14)*Settings!$B$25 -> 2500 | V14: =SUM(O14:P14)+SUM(R14:U14) -> 16571.429 | W14: =N14-V14 -> 39082.321 | X14: =IF(N14>0,W14/N14,0) -> 0.70224058 | Y14: =Q14*60/Settings!$B$9 -> 9.6428571 | Z14: =IF(Y14>0,W14/Y14*60,0) -> 243178.89 | AA14: =IF(Z14>0,G14/Z14,"Never") -> 20.560995 | AB14: =INDEX(Vehicles!$S$5:$S$16,MATCH($B14,Vehicles!$A$5:$A$16,0))&" to "&INDEX(Vehicles!$T$5:$T$16,MATCH($B14,Vehicles!$A$5:$A$16,0)) -> 20 to 80 | AC14: =IF(NOT(ISNUMBER(AA14)),"Loses money",IF(AA14<INDEX(Vehicles!$S$5:$S$16,MATCH($B14,Vehicles!$A$5:$A$16,0)),"Too fast",IF(AA14>INDEX(Vehicles!$T$5:$T$16,MATCH($B14,Vehicles!$A$5:$A$16,0)),"Too slow","OK"))) -> OK | AD14: =24/Q14 -> 2.4888889 | AE14: =INDEX(Routes!$I$5:$I$20,MATCH($C14,Routes!$A$5:$A$20,0))/(I14*AD14) -> 12.605042 | AF14: =IF(AND(INDEX(Vehicles!$Q$5:$Q$16,MATCH($B14,Vehicles!$A$5:$A$16,0))="No",K14="Line"),"Not allowed on highway",IF(AND(K14="Line",L14>Settings!$B$26),"Line haul too long",IF(ISERROR(SEARCH(","&B14&",",","&INDEX(Cargo!$C$4:$C$15,MATCH($D14,Cargo!$A$4:$A$15,0))&",")),"Cargo not allowed on this vehicle","")))
A15: Tier 11 typical | B15: 11 | C15: R05 | D15: Containers | E15: 0 | F15: =INDEX(Vehicles!$B$5:$B$16,MATCH($B15,Vehicles!$A$5:$A$16,0)) -> Bongo Mover 40 | G15: =INDEX(Vehicles!$E$5:$E$16,MATCH($B15,Vehicles!$A$5:$A$16,0)) -> 6500000 | H15: =INDEX(Vehicles!$F$5:$F$16,MATCH($B15,Vehicles!$A$5:$A$16,0)) -> 28 | I15: =H15+MAX(0,MIN(E15,INDEX(Vehicles!$G$5:$G$16,MATCH($B15,Vehicles!$A$5:$A$16,0))-H15)) -> 28 | J15: =(I15-H15)/H15 -> 0 | K15: =INDEX(Routes!$E$5:$E$20,MATCH($C15,Routes!$A$5:$A$20,0)) -> Line | L15: =INDEX(Routes!$D$5:$D$20,MATCH($C15,Routes!$A$5:$A$20,0)) -> 250 | M15: =IF(K15="Local",2*L15,L15) -> 250 | N15: =I15*(Settings!$B$6+Settings!$B$7*L15)*INDEX(Cargo!$B$4:$B$15,MATCH($D15,Cargo!$A$4:$A$15,0))*INDEX(Vehicles!$O$5:$O$16,MATCH($B15,Vehicles!$A$5:$A$16,0))*Settings!$B$8 -> 73332 | O15: =M15*INDEX(Vehicles!$K$5:$K$16,MATCH($B15,Vehicles!$A$5:$A$16,0))*(1+Settings!$B$18*J15) -> 13500 | P15: =INDEX(Tolls!$B$5:$F$11,MATCH(INDEX(Vehicles!$P$5:$P$16,MATCH($B15,Vehicles!$A$5:$A$16,0)),Tolls!$A$5:$A$11,0),MATCH(INDEX(Routes!$F$5:$F$20,MATCH($C15,Routes!$A$5:$A$20,0)),Tolls!$B$4:$F$4,0))*IF(K15="Local",2,1) -> 2500 | Q15: =M15/INDEX(Vehicles!$H$5:$H$16,MATCH($B15,Vehicles!$A$5:$A$16,0))+INDEX(Vehicles!$N$5:$N$16,MATCH($B15,Vehicles!$A$5:$A$16,0))+INDEX(Routes!$H$5:$H$20,MATCH($C15,Routes!$A$5:$A$20,0)) -> 10.642857 | R15: =Q15*INDEX(Vehicles!$M$5:$M$16,MATCH($B15,Vehicles!$A$5:$A$16,0)) -> 2341.4286 | S15: =M15*INDEX(Vehicles!$L$5:$L$16,MATCH($B15,Vehicles!$A$5:$A$16,0))*(1+Settings!$B$19*J15) -> 2250 | T15: =IF(I15>H15,INDEX(Routes!$G$5:$G$20,MATCH($C15,Routes!$A$5:$A$20,0))*Settings!$B$20*(Settings!$B$21+Settings!$B$22*(I15-H15)),0) -> 0 | U15: =G15*Settings!$B$23*M15/100*(1+Settings!$B$24*J15)*Settings!$B$25 -> 3250 | V15: =SUM(O15:P15)+SUM(R15:U15) -> 23841.429 | W15: =N15-V15 -> 49490.571 | X15: =IF(N15>0,W15/N15,0) -> 0.6748837 | Y15: =Q15*60/Settings!$B$9 -> 10.642857 | Z15: =IF(Y15>0,W15/Y15*60,0) -> 279007.25 | AA15: =IF(Z15>0,G15/Z15,"Never") -> 23.296886 | AB15: =INDEX(Vehicles!$S$5:$S$16,MATCH($B15,Vehicles!$A$5:$A$16,0))&" to "&INDEX(Vehicles!$T$5:$T$16,MATCH($B15,Vehicles!$A$5:$A$16,0)) -> 20 to 80 | AC15: =IF(NOT(ISNUMBER(AA15)),"Loses money",IF(AA15<INDEX(Vehicles!$S$5:$S$16,MATCH($B15,Vehicles!$A$5:$A$16,0)),"Too fast",IF(AA15>INDEX(Vehicles!$T$5:$T$16,MATCH($B15,Vehicles!$A$5:$A$16,0)),"Too slow","OK"))) -> OK | AD15: =24/Q15 -> 2.2550336 | AE15: =INDEX(Routes!$I$5:$I$20,MATCH($C15,Routes!$A$5:$A$20,0))/(I15*AD15) -> 6.335034 | AF15: =IF(AND(INDEX(Vehicles!$Q$5:$Q$16,MATCH($B15,Vehicles!$A$5:$A$16,0))="No",K15="Line"),"Not allowed on highway",IF(AND(K15="Line",L15>Settings!$B$26),"Line haul too long",IF(ISERROR(SEARCH(","&B15&",",","&INDEX(Cargo!$C$4:$C$15,MATCH($D15,Cargo!$A$4:$A$15,0))&",")),"Cargo not allowed on this vehicle","")))
A16: Tier 12 typical | B16: 12 | C16: R05 | D16: Heavy machinery | E16: 0 | F16: =INDEX(Vehicles!$B$5:$B$16,MATCH($B16,Vehicles!$A$5:$A$16,0)) -> Hati Lowbed | G16: =INDEX(Vehicles!$E$5:$E$16,MATCH($B16,Vehicles!$A$5:$A$16,0)) -> 8000000 | H16: =INDEX(Vehicles!$F$5:$F$16,MATCH($B16,Vehicles!$A$5:$A$16,0)) -> 40 | I16: =H16+MAX(0,MIN(E16,INDEX(Vehicles!$G$5:$G$16,MATCH($B16,Vehicles!$A$5:$A$16,0))-H16)) -> 40 | J16: =(I16-H16)/H16 -> 0 | K16: =INDEX(Routes!$E$5:$E$20,MATCH($C16,Routes!$A$5:$A$20,0)) -> Line | L16: =INDEX(Routes!$D$5:$D$20,MATCH($C16,Routes!$A$5:$A$20,0)) -> 250 | M16: =IF(K16="Local",2*L16,L16) -> 250 | N16: =I16*(Settings!$B$6+Settings!$B$7*L16)*INDEX(Cargo!$B$4:$B$15,MATCH($D16,Cargo!$A$4:$A$15,0))*INDEX(Vehicles!$O$5:$O$16,MATCH($B16,Vehicles!$A$5:$A$16,0))*Settings!$B$8 -> 104760 | O16: =M16*INDEX(Vehicles!$K$5:$K$16,MATCH($B16,Vehicles!$A$5:$A$16,0))*(1+Settings!$B$18*J16) -> 16875 | P16: =INDEX(Tolls!$B$5:$F$11,MATCH(INDEX(Vehicles!$P$5:$P$16,MATCH($B16,Vehicles!$A$5:$A$16,0)),Tolls!$A$5:$A$11,0),MATCH(INDEX(Routes!$F$5:$F$20,MATCH($C16,Routes!$A$5:$A$20,0)),Tolls!$B$4:$F$4,0))*IF(K16="Local",2,1) -> 3000 | Q16: =M16/INDEX(Vehicles!$H$5:$H$16,MATCH($B16,Vehicles!$A$5:$A$16,0))+INDEX(Vehicles!$N$5:$N$16,MATCH($B16,Vehicles!$A$5:$A$16,0))+INDEX(Routes!$H$5:$H$20,MATCH($C16,Routes!$A$5:$A$20,0)) -> 14 | R16: =Q16*INDEX(Vehicles!$M$5:$M$16,MATCH($B16,Vehicles!$A$5:$A$16,0)) -> 3640 | S16: =M16*INDEX(Vehicles!$L$5:$L$16,MATCH($B16,Vehicles!$A$5:$A$16,0))*(1+Settings!$B$19*J16) -> 3000 | T16: =IF(I16>H16,INDEX(Routes!$G$5:$G$20,MATCH($C16,Routes!$A$5:$A$20,0))*Settings!$B$20*(Settings!$B$21+Settings!$B$22*(I16-H16)),0) -> 0 | U16: =G16*Settings!$B$23*M16/100*(1+Settings!$B$24*J16)*Settings!$B$25 -> 4000 | V16: =SUM(O16:P16)+SUM(R16:U16) -> 30515 | W16: =N16-V16 -> 74245 | X16: =IF(N16>0,W16/N16,0) -> 0.70871516 | Y16: =Q16*60/Settings!$B$9 -> 14 | Z16: =IF(Y16>0,W16/Y16*60,0) -> 318192.86 | AA16: =IF(Z16>0,G16/Z16,"Never") -> 25.141985 | AB16: =INDEX(Vehicles!$S$5:$S$16,MATCH($B16,Vehicles!$A$5:$A$16,0))&" to "&INDEX(Vehicles!$T$5:$T$16,MATCH($B16,Vehicles!$A$5:$A$16,0)) -> 20 to 80 | AC16: =IF(NOT(ISNUMBER(AA16)),"Loses money",IF(AA16<INDEX(Vehicles!$S$5:$S$16,MATCH($B16,Vehicles!$A$5:$A$16,0)),"Too fast",IF(AA16>INDEX(Vehicles!$T$5:$T$16,MATCH($B16,Vehicles!$A$5:$A$16,0)),"Too slow","OK"))) -> OK | AD16: =24/Q16 -> 1.7142857 | AE16: =INDEX(Routes!$I$5:$I$20,MATCH($C16,Routes!$A$5:$A$20,0))/(I16*AD16) -> 5.8333333 | AF16: =IF(AND(INDEX(Vehicles!$Q$5:$Q$16,MATCH($B16,Vehicles!$A$5:$A$16,0))="No",K16="Line"),"Not allowed on highway",IF(AND(K16="Line",L16>Settings!$B$26),"Line haul too long",IF(ISERROR(SEARCH(","&B16&",",","&INDEX(Cargo!$C$4:$C$15,MATCH($D16,Cargo!$A$4:$A$15,0))&",")),"Cargo not allowed on this vehicle","")))
... A26: Rule check: van on highway | B26: 1 | C26: R05 | D26: General dry | E26: 0 | F26: =INDEX(Vehicles!$B$5:$B$16,MATCH($B26,Vehicles!$A$5:$A$16,0)) -> Sonar Van | G26: =INDEX(Vehicles!$E$5:$E$16,MATCH($B26,Vehicles!$A$5:$A$16,0)) -> 20000 | H26: =INDEX(Vehicles!$F$5:$F$16,MATCH($B26,Vehicles!$A$5:$A$16,0)) -> 0.3 | I26: =H26+MAX(0,MIN(E26,INDEX(Vehicles!$G$5:$G$16,MATCH($B26,Vehicles!$A$5:$A$16,0))-H26)) -> 0.3 | J26: =(I26-H26)/H26 -> 0 | K26: =INDEX(Routes!$E$5:$E$20,MATCH($C26,Routes!$A$5:$A$20,0)) -> Line | L26: =INDEX(Routes!$D$5:$D$20,MATCH($C26,Routes!$A$5:$A$20,0)) -> 250 | M26: =IF(K26="Local",2*L26,L26) -> 250 | N26: =I26*(Settings!$B$6+Settings!$B$7*L26)*INDEX(Cargo!$B$4:$B$15,MATCH($D26,Cargo!$A$4:$A$15,0))*INDEX(Vehicles!$O$5:$O$16,MATCH($B26,Vehicles!$A$5:$A$16,0))*Settings!$B$8 -> 2728.125 | O26: =M26*INDEX(Vehicles!$K$5:$K$16,MATCH($B26,Vehicles!$A$5:$A$16,0))*(1+Settings!$B$18*J26) -> 0 | P26: =INDEX(Tolls!$B$5:$F$11,MATCH(INDEX(Vehicles!$P$5:$P$16,MATCH($B26,Vehicles!$A$5:$A$16,0)),Tolls!$A$5:$A$11,0),MATCH(INDEX(Routes!$F$5:$F$20,MATCH($C26,Routes!$A$5:$A$20,0)),Tolls!$B$4:$F$4,0))*IF(K26="Local",2,1) -> 0 | Q26: =M26/INDEX(Vehicles!$H$5:$H$16,MATCH($B26,Vehicles!$A$5:$A$16,0))+INDEX(Vehicles!$N$5:$N$16,MATCH($B26,Vehicles!$A$5:$A$16,0))+INDEX(Routes!$H$5:$H$20,MATCH($C26,Routes!$A$5:$A$20,0)) -> 32.55 | R26: =Q26*INDEX(Vehicles!$M$5:$M$16,MATCH($B26,Vehicles!$A$5:$A$16,0)) -> 1627.5 | S26: =M26*INDEX(Vehicles!$L$5:$L$16,MATCH($B26,Vehicles!$A$5:$A$16,0))*(1+Settings!$B$19*J26) -> 50 | T26: =IF(I26>H26,INDEX(Routes!$G$5:$G$20,MATCH($C26,Routes!$A$5:$A$20,0))*Settings!$B$20*(Settings!$B$21+Settings!$B$22*(I26-H26)),0) -> 0 | U26: =G26*Settings!$B$23*M26/100*(1+Settings!$B$24*J26)*Settings!$B$25 -> 10 | V26: =SUM(O26:P26)+SUM(R26:U26) -> 1687.5 | W26: =N26-V26 -> 1040.625 | X26: =IF(N26>0,W26/N26,0) -> 0.3814433 | Y26: =Q26*60/Settings!$B$9 -> 32.55 | Z26: =IF(Y26>0,W26/Y26*60,0) -> 1918.2028 | AA26: =IF(Z26>0,G26/Z26,"Never") -> 10.426426 | AB26: =INDEX(Vehicles!$S$5:$S$16,MATCH($B26,Vehicles!$A$5:$A$16,0))&" to "&INDEX(Vehicles!$T$5:$T$16,MATCH($B26,Vehicles!$A$5:$A$16,0)) -> 0.5 to 5 | AC26: =IF(NOT(ISNUMBER(AA26)),"Loses money",IF(AA26<INDEX(Vehicles!$S$5:$S$16,MATCH($B26,Vehicles!$A$5:$A$16,0)),"Too fast",IF(AA26>INDEX(Vehicles!$T$5:$T$16,MATCH($B26,Vehicles!$A$5:$A$16,0)),"Too slow","OK"))) -> Too slow | AD26: =24/Q26 -> 0.73732719 | AE26: =INDEX(Routes!$I$5:$I$20,MATCH($C26,Routes!$A$5:$A$20,0))/(I26*AD26) -> 1808.3333 | AF26: =IF(AND(INDEX(Vehicles!$Q$5:$Q$16,MATCH($B26,Vehicles!$A$5:$A$16,0))="No",K26="Line"),"Not allowed on highway",IF(AND(K26="Line",L26>Settings!$B$26),"Line haul too long",IF(ISERROR(SEARCH(","&B26&",",","&INDEX(Cargo!$C$4:$C$15,MATCH($D26,Cargo!$A$4:$A$15,0))&",")),"Cargo not allowed on this vehicle",""))) -> Not allowed on highway

Sheet First Hour
A1: First hours of play: greedy purchase simulation
A2: The player starts with the starting cash and one free Sathi Plus, then buys the next queue item as soon as cash allows (at most one per 5 minutes).
A4: Starting cash (Tk) | B4: =Settings!$B$16 -> 1500000 | F4: Purchases in first 60 min | G4: =COUNTIFS($A$17:$A$65,"<60",$F$17:$F$65,1) -> 3
A5: Starter vehicle profit per real hour at 1x (Tk) | B5: ='Trip Calculator'!Z8 -> 90246.429 | F5: Purchases in first 4 hours | G5: =SUM($F$17:$F$65) -> 4
F6: Fleet profit per hour after Turbo Start (Tk) | G6: =INDEX($H$17:$H$65,MATCH(Settings!$B$14,$A$17:$A$65,0)) -> 247606.66
A7: # | B7: Purchase queue item | C7: Price (Tk) | D7: Adds profit per real hour at 1x (Tk)
A8: 1 | B8: Tuntuni Mini on Dhaka city route | C8: ='Trip Calculator'!G7 -> 1000000 | D8: ='Trip Calculator'!Z7 -> 74897.727
A9: 2 | B9: Sathi Plus to Narayanganj | C9: ='Trip Calculator'!G23 -> 1300000 | D9: ='Trip Calculator'!Z23 -> 82462.5
A10: 3 | B10: Terminal in Gazipur | C10: =Settings!$B$17 -> 800000 | D10: 0
A11: 4 | B11: Sathi Plus to Gazipur | C11: ='Trip Calculator'!G25 -> 1300000 | D11: ='Trip Calculator'!Z25 -> 61568.75
A12: 5 | B12: Meghna 14 Dhaka-Cumilla | C12: ='Trip Calculator'!G24 -> 2500000 | D12: ='Trip Calculator'!Z24 -> 123201.49
A13: 6 | B13: Jamuna Open Dhaka-Chattogram | C13: ='Trip Calculator'!G10 -> 3200000 | D13: ='Trip Calculator'!Z10 -> 155643.24
A16: Real minute | B16: Speed (x) | C16: Income this step (Tk) | D16: Cash before buying (Tk) | E16: Next queue item # | F16: Bought? (1 = yes) | G16: Cash after (Tk) | H16: Fleet profit per real hour at 1x (Tk) | I16: Event
A17: 0 | B17: =IF(A17<Settings!$B$10,Settings!$B$11,IF(A17<Settings!$B$12,Settings!$B$13,IF(A17<Settings!$B$14,Settings!$B$15,1))) -> 20 | C17: 0 | D17: =$B$4 -> 1500000 | E17: 1 | F17: =IF(E17<=6,IF(D17>=INDEX($C$8:$C$13,E17),1,0),0) -> 1 | G17: =D17-F17*IF(E17<=6,INDEX($C$8:$C$13,E17),0) -> 500000 | H17: =$B$5+F17*IF(E17<=6,INDEX($D$8:$D$13,E17),0) -> 165144.16 | I17: =IF(F17=1,"Bought: "&INDEX($B$8:$B$13,E17),"") -> Bought: Tuntuni Mini on Dhaka city route
A18: 5 | B18: =IF(A18<Settings!$B$10,Settings!$B$11,IF(A18<Settings!$B$12,Settings!$B$13,IF(A18<Settings!$B$14,Settings!$B$15,1))) -> 20 | C18: =H17*B17*5/60 -> 275240.26 | D18: =G17+C18 -> 775240.26 | E18: =E17+F17 -> 2 | F18: =IF(E18<=6,IF(D18>=INDEX($C$8:$C$13,E18),1,0),0) -> 0 | G18: =D18-F18*IF(E18<=6,INDEX($C$8:$C$13,E18),0) -> 775240.26 | H18: =H17+F18*IF(E18<=6,INDEX($D$8:$D$13,E18),0) -> 165144.16 | I18: =IF(F18=1,"Bought: "&INDEX($B$8:$B$13,E18),"")
A19: 10 | B19: =IF(A19<Settings!$B$10,Settings!$B$11,IF(A19<Settings!$B$12,Settings!$B$13,IF(A19<Settings!$B$14,Settings!$B$15,1))) -> 20 | C19: =H18*B18*5/60 -> 275240.26 | D19: =G18+C19 -> 1050480.5 | E19: =E18+F18 -> 2 | F19: =IF(E19<=6,IF(D19>=INDEX($C$8:$C$13,E19),1,0),0) -> 0 | G19: =D19-F19*IF(E19<=6,INDEX($C$8:$C$13,E19),0) -> 1050480.5 | H19: =H18+F19*IF(E19<=6,INDEX($D$8:$D$13,E19),0) -> 165144.16 | I19: =IF(F19=1,"Bought: "&INDEX($B$8:$B$13,E19),"")
A20: 15 | B20: =IF(A20<Settings!$B$10,Settings!$B$11,IF(A20<Settings!$B$12,Settings!$B$13,IF(A20<Settings!$B$14,Settings!$B$15,1))) -> 20 | C20: =H19*B19*5/60 -> 275240.26 | D20: =G19+C20 -> 1325720.8 | E20: =E19+F19 -> 2 | F20: =IF(E20<=6,IF(D20>=INDEX($C$8:$C$13,E20),1,0),0) -> 1 | G20: =D20-F20*IF(E20<=6,INDEX($C$8:$C$13,E20),0) -> 25720.779 | H20: =H19+F20*IF(E20<=6,INDEX($D$8:$D$13,E20),0) -> 247606.66 | I20: =IF(F20=1,"Bought: "&INDEX($B$8:$B$13,E20),"") -> Bought: Sathi Plus to Narayanganj
A21: 20 | B21: =IF(A21<Settings!$B$10,Settings!$B$11,IF(A21<Settings!$B$12,Settings!$B$13,IF(A21<Settings!$B$14,Settings!$B$15,1))) -> 10 | C21: =H20*B20*5/60 -> 412677.76 | D21: =G20+C21 -> 438398.54 | E21: =E20+F20 -> 3 | F21: =IF(E21<=6,IF(D21>=INDEX($C$8:$C$13,E21),1,0),0) -> 0 | G21: =D21-F21*IF(E21<=6,INDEX($C$8:$C$13,E21),0) -> 438398.54 | H21: =H20+F21*IF(E21<=6,INDEX($D$8:$D$13,E21),0) -> 247606.66 | I21: =IF(F21=1,"Bought: "&INDEX($B$8:$B$13,E21),"")
